Workbook

Sheet Premissas
A1: Projeção de tráfego pago — Consultoria de treino e dieta
A2: Legenda: texto azul = dado ou hipótese que você pode editar · texto preto = fórmula · texto verde = vem de outra aba · fundo amarelo = hipótese principal a validar com campanha real
A4: DADOS DO CLIENTE
A5: Custo mensal da operação (R$) | B5: 18000 | C5: Informado pelo cliente (equipe, ferramentas, estrutura; não inclui verba de anúncios)
A6: Alunos ativos hoje | B6: 187 | C6: Informado: 185 a 190; usado o ponto médio
A7: Entradas novas por mês (orgânico) | B7: 16 | C7: Informado; a média real de jun–set é 15,75
A8: Fechamento do orgânico (leads → alunos) | B8: =1/6 -> 0.16666667 | C8: Informado: 1 a cada 6; oscilou nos últimos 3 meses
A9: Leads orgânicos por mês (estimado) | B9: =B7/B8 -> 96 | C9: Estimado a partir das entradas e do fechamento; o cliente relata 40 a 200 por mês, média ~95
A10: Capacidade de entradas novas por mês | B10: 35 | C10: Informado pelo cliente
A11: Teto de alunos ativos (vagas fecham ao atingir) | B11: 230 | C11: Informado pelo cliente: 230 é o número ideal; ao atingir, fecham as vagas por um tempo
A12: Permanência média / LTV (meses) | B12: 6 | C12: Informado pelo cliente
A13: Desconto aplicado aos preços | B13: 0 | C13: 0% = preço normal · 10% = condição da Black Friday
A15: PLANOS E MIX DE VENDAS (jun–set, informado pelo cliente)
A16: Plano | B16: Preço cheio (R$) | C16: Meses do plano | D16: Alunos novos jun–set | E16: Peso no mix | F16: Valor mensal (R$)
A17: Trimestral | B17: 899 | C17: 3 | D17: 33 | E17: =D17/$D$20 -> 0.52380952 | F17: =B17/C17 -> 299.66667
A18: Semestral | B18: 1349 | C18: 6 | D18: 27 | E18: =D18/$D$20 -> 0.42857143 | F18: =B18/C18 -> 224.83333
A19: Anual | B19: 2349 | C19: 12 | D19: 3 | E19: =D19/$D$20 -> 0.047619048 | F19: =B19/C19 -> 195.75
A20: Total | D20: =SUM(D17:D19) -> 63 | E20: =SUM(E17:E19) -> 1
A21: Entradas por mês: jun 18 · jul 4 · ago 18 · set 23 (informado pelo cliente)
A22: INDICADORES CALCULADOS
A23: Ticket médio da 1ª compra (R$) | B23: =SUMPRODUCT(B17:B19,D17:D19)/D20*(1-B13) -> 1160.9048 | C23: Preço de cada plano ponderado pelo mix, já com o desconto
A24: Valor mensal médio por aluno (R$) | B24: =SUMPRODUCT(F17:F19,D17:D19)/D20*(1-B13) -> 262.64683 | C24: Valor mensal de cada plano ponderado pelo mix
A25: LTV bruto no período (R$) | B25: =B24*B12 -> 1575.881 | C25: Valor mensal médio × permanência (aproximação)
A26: Custo de atendimento por aluno/mês (R$) | B26: =B5/B6 -> 96.256684 | C26: Custo da operação ÷ alunos ativos
A27: Custo de atendimento no período (R$) | B27: =B26*B12 -> 577.54011 | C27: Custo mensal por aluno × permanência
A28: Contribuição por aluno novo = CAC de equilíbrio (R$) | B28: =B25-B27 -> 998.34085 | C28: Acima desse CAC, o aluno dá prejuízo na permanência
A29: Folga de capacidade para entradas via tráfego (alunos/mês) | B29: =B10-B7 -> 19 | C29: Capacidade de entradas menos as entradas orgânicas
A30: Entradas extras/mês para manter a base no teto (alunos/mês) | B30: =(B11-B6)/B12 -> 7.1666667 | C30: (teto − ativos hoje) ÷ permanência; é o ritmo do tráfego depois que a base lota
A31: CENÁRIOS DE TRÁFEGO (hipóteses a validar nas primeiras 2 a 4 semanas)
A32: Cenário | B32: CPL (R$ por conversa no WhatsApp) | C32: Fechamento do tráfego | D32: CAC resultante (R$)
A33: Conservador | B33: 50 | C33: 0.08 | D33: =B33/C33 -> 625
A34: Realista | B34: 35 | C34: 0.12 | D34: =B34/C34 -> 291.66667
A35: Otimista | B35: 25 | C35: =B8 -> 0.16666667 | D35: =B35/C35 -> 150 | E35: Otimista = o tráfego fecha tanto quanto o orgânico
A37: FAIXAS DE VERBA MENSAL EM ANÚNCIOS (R$)
A38: Faixa 1 | B38: 3000
A39: Faixa 2 | B39: 5000
A40: Faixa 3 | B40: 8000
A42: NOTAS E LIMITAÇÕES
A43: 1. Vêm do cliente: custo, alunos ativos, entradas, capacidade de entradas (35/mês), teto de 230 alunos ativos, LTV, mix de planos (jun–set), fechamento do orgânico e faixa de leads.
A44: 2. São hipóteses minhas, não benchmarks verificados: CPL e fechamento dos 3 cenários e as faixas de verba. Substituir por dados reais após 2 a 4 semanas de campanha.
...

Sheet Projeção
A1: Projeção por cenário e faixa de verba (resultado mensal)
A2: Todos os valores vêm da aba Premissas; altere lá e esta aba recalcula.
A4: Cenário | B4: Verba/mês (R$) | C4: CPL (R$) | D4: Fechamento | E4: CAC (R$) | F4: Leads pagos/mês | G4: Alunos novos (potencial) | H4: Alunos novos (limitado pela capacidade) | I4: Conversas totais/mês (orgânico + pago) | J4: Receita da 1ª compra (R$) | K4: Contribuição na permanência (R$) | L4: Resultado líquido (R$) | M4: Retorno (contribuição ÷ verba) | N4: Base ativa em regime (sem fechar vagas) | O4: Alerta | P4: Meses até lotar o teto de alunos ativos | Q4: Verba/mês para manter a base no teto (R$)
A5: =Premissas!$A$33 -> Conservador | B5: =Premissas!$B$38 -> 3000 | C5: =Premissas!$B$33 -> 50 | D5: =Premissas!$C$33 -> 0.08 | E5: =C5/D5 -> 625 | F5: =B5/C5 -> 60 | G5: =F5*D5 -> 4.8 | H5: =MIN(G5,Premissas!$B$29) -> 4.8 | I5: =Premissas!$B$9+F5 -> 156 | J5: =H5*Premissas!$B$23 -> 5572.3429 | K5: =H5*Premissas!$B$28 -> 4792.0361 | L5: =K5-B5 -> 1792.0361 | M5: =K5/B5 -> 1.5973454 | N5: =Premissas!$B$6+H5*Premissas!$B$12 -> 215.8 | O5: =IF(G5>Premissas!$B$29,"Passa da folga de entradas (35/mês)",IF(N5>Premissas!$B$11,"Lota o teto: fechar vagas","OK")) -> OK | P5: =IF(H5*Premissas!$B$12<Premissas!$B$11-Premissas!$B$6,"Não lota",(Premissas!$B$11-Premissas!$B$6)/H5) -> Não lota | Q5: =Premissas!$B$30*E5 -> 4479.1667
A6: =Premissas!$A$33 -> Conservador | B6: =Premissas!$B$39 -> 5000 | C6: =Premissas!$B$33 -> 50 | D6: =Premissas!$C$33 -> 0.08 | E6: =C6/D6 -> 625 | F6: =B6/C6 -> 100 | G6: =F6*D6 -> 8 | H6: =MIN(G6,Premissas!$B$29) -> 8 | I6: =Premissas!$B$9+F6 -> 196 | J6: =H6*Premissas!$B$23 -> 9287.2381 | K6: =H6*Premissas!$B$28 -> 7986.7268 | L6: =K6-B6 -> 2986.7268 | M6: =K6/B6 -> 1.5973454 | N6: =Premissas!$B$6+H6*Premissas!$B$12 -> 235 | O6: =IF(G6>Premissas!$B$29,"Passa da folga de entradas (35/mês)",IF(N6>Premissas!$B$11,"Lota o teto: fechar vagas","OK")) -> Lota o teto: fechar vagas | P6: =IF(H6*Premissas!$B$12<Premissas!$B$11-Premissas!$B$6,"Não lota",(Premissas!$B$11-Premissas!$B$6)/H6) -> 5.375 | Q6: =Premissas!$B$30*E6 -> 4479.1667
A7: =Premissas!$A$33 -> Conservador | B7: =Premissas!$B$40 -> 8000 | C7: =Premissas!$B$33 -> 50 | D7: =Premissas!$C$33 -> 0.08 | E7: =C7/D7 -> 625 | F7: =B7/C7 -> 160 | G7: =F7*D7 -> 12.8 | H7: =MIN(G7,Premissas!$B$29) -> 12.8 | I7: =Premissas!$B$9+F7 -> 256 | J7: =H7*Premissas!$B$23 -> 14859.581 | K7: =H7*Premissas!$B$28 -> 12778.763 | L7: =K7-B7 -> 4778.7628 | M7: =K7/B7 -> 1.5973454 | N7: =Premissas!$B$6+H7*Premissas!$B$12 -> 263.8 | O7: =IF(G7>Premissas!$B$29,"Passa da folga de entradas (35/mês)",IF(N7>Premissas!$B$11,"Lota o teto: fechar vagas","OK")) -> Lota o teto: fechar vagas | P7: =IF(H7*Premissas!$B$12<Premissas!$B$11-Premissas!$B$6,"Não lota",(Premissas!$B$11-Premissas!$B$6)/H7) -> 3.359375 | Q7: =Premissas!$B$30*E7 -> 4479.1667
A8: =Premissas!$A$34 -> Realista | B8: =Premissas!$B$38 -> 3000 | C8: =Premissas!$B$34 -> 35 | D8: =Premissas!$C$34 -> 0.12 | E8: =C8/D8 -> 291.66667 | F8: =B8/C8 -> 85.714286 | G8: =F8*D8 -> 10.285714 | H8: =MIN(G8,Premissas!$B$29) -> 10.285714 | I8: =Premissas!$B$9+F8 -> 181.71429 | J8: =H8*Premissas!$B$23 -> 11940.735 | K8: =H8*Premissas!$B$28 -> 10268.649 | L8: =K8-B8 -> 7268.6487 | M8: =K8/B8 -> 3.4228829 | N8: =Premissas!$B$6+H8*Premissas!$B$12 -> 248.71429 | O8: =IF(G8>Premissas!$B$29,"Passa da folga de entradas (35/mês)",IF(N8>Premissas!$B$11,"Lota o teto: fechar vagas","OK")) -> Lota o teto: fechar vagas | P8: =IF(H8*Premissas!$B$12<Premissas!$B$11-Premissas!$B$6,"Não lota",(Premissas!$B$11-Premissas!$B$6)/H8) -> 4.1805556 | Q8: =Premissas!$B$30*E8 -> 2090.2778
A9: =Premissas!$A$34 -> Realista | B9: =Premissas!$B$39 -> 5000 | C9: =Premissas!$B$34 -> 35 | D9: =Premissas!$C$34 -> 0.12 | E9: =C9/D9 -> 291.66667 | F9: =B9/C9 -> 142.85714 | G9: =F9*D9 -> 17.142857 | H9: =MIN(G9,Premissas!$B$29) -> 17.142857 | I9: =Premissas!$B$9+F9 -> 238.85714 | J9: =H9*Premissas!$B$23 -> 19901.224 | K9: =H9*Premissas!$B$28 -> 17114.414 | L9: =K9-B9 -> 12114.414 | M9: =K9/B9 -> 3.4228829 | N9: =Premissas!$B$6+H9*Premissas!$B$12 -> 289.85714 | O9: =IF(G9>Premissas!$B$29,"Passa da folga de entradas (35/mês)",IF(N9>Premissas!$B$11,"Lota o teto: fechar vagas","OK")) -> Lota o teto: fechar vagas | P9: =IF(H9*Premissas!$B$12<Premissas!$B$11-Premissas!$B$6,"Não lota",(Premissas!$B$11-Premissas!$B$6)/H9) -> 2.5083333 | Q9: =Premissas!$B$30*E9 -> 2090.2778
A10: =Premissas!$A$34 -> Realista | B10: =Premissas!$B$40 -> 8000 | C10: =Premissas!$B$34 -> 35 | D10: =Premissas!$C$34 -> 0.12 | E10: =C10/D10 -> 291.66667 | F10: =B10/C10 -> 228.57143 | G10: =F10*D10 -> 27.428571 | H10: =MIN(G10,Premissas!$B$29) -> 19 | I10: =Premissas!$B$9+F10 -> 324.57143 | J10: =H10*Premissas!$B$23 -> 22057.19 | K10: =H10*Premissas!$B$28 -> 18968.476 | L10: =K10-B10 -> 10968.476 | M10: =K10/B10 -> 2.3710595 | N10: =Premissas!$B$6+H10*Premissas!$B$12 -> 301 | O10: =IF(G10>Premissas!$B$29,"Passa da folga de entradas (35/mês)",IF(N10>Premissas!$B$11,"Lota o teto: fechar vagas","OK")) -> Passa da folga de entradas (35/mês) | P10: =IF(H10*Premissas!$B$12<Premissas!$B$11-Premissas!$B$6,"Não lota",(Premissas!$B$11-Premissas!$B$6)/H10) -> 2.2631579 | Q10: =Premissas!$B$30*E10 -> 2090.2778
A11: =Premissas!$A$35 -> Otimista | B11: =Premissas!$B$38 -> 3000 | C11: =Premissas!$B$35 -> 25 | D11: =Premissas!$C$35 -> 0.16666667 | E11: =C11/D11 -> 150 | F11: =B11/C11 -> 120 | G11: =F11*D11 -> 20 | H11: =MIN(G11,Premissas!$B$29) -> 19 | I11: =Premissas!$B$9+F11 -> 216 | J11: =H11*Premissas!$B$23 -> 22057.19 | K11: =H11*Premissas!$B$28 -> 18968.476 | L11: =K11-B11 -> 15968.476 | M11: =K11/B11 -> 6.3228254 | N11: =Premissas!$B$6+H11*Premissas!$B$12 -> 301 | O11: =IF(G11>Premissas!$B$29,"Passa da folga de entradas (35/mês)",IF(N11>Premissas!$B$11,"Lota o teto: fechar vagas","OK")) -> Passa da folga de entradas (35/mês) | P11: =IF(H11*Premissas!$B$12<Premissas!$B$11-Premissas!$B$6,"Não lota",(Premissas!$B$11-Premissas!$B$6)/H11) -> 2.2631579 | Q11: =Premissas!$B$30*E11 -> 1075
A12: =Premissas!$A$35 -> Otimista | B12: =Premissas!$B$39 -> 5000 | C12: =Premissas!$B$35 -> 25 | D12: =Premissas!$C$35 -> 0.16666667 | E12: =C12/D12 -> 150 | F12: =B12/C12 -> 200 | G12: =F12*D12 -> 33.333333 | H12: =MIN(G12,Premissas!$B$29) -> 19 | I12: =Premissas!$B$9+F12 -> 296 | J12: =H12*Premissas!$B$23 -> 22057.19 | K12: =H12*Premissas!$B$28 -> 18968.476 | L12: =K12-B12 -> 13968.476 | M12: =K12/B12 -> 3.7936952 | N12: =Premissas!$B$6+H12*Premissas!$B$12 -> 301 | O12: =IF(G12>Premissas!$B$29,"Passa da folga de entradas (35/mês)",IF(N12>Premissas!$B$11,"Lota o teto: fechar vagas","OK")) -> Passa da folga de entradas (35/mês) | P12: =IF(H12*Premissas!$B$12<Premissas!$B$11-Premissas!$B$6,"Não lota",(Premissas!$B$11-Premissas!$B$6)/H12) -> 2.2631579 | Q12: =Premissas!$B$30*E12 -> 1075
A13: =Premissas!$A$35 -> Otimista | B13: =Premissas!$B$40 -> 8000 | C13: =Premissas!$B$35 -> 25 | D13: =Premissas!$C$35 -> 0.16666667 | E13: =C13/D13 -> 150 | F13: =B13/C13 -> 320 | G13: =F13*D13 -> 53.333333 | H13: =MIN(G13,Premissas!$B$29) -> 19 | I13: =Premissas!$B$9+F13 -> 416 | J13: =H13*Premissas!$B$23 -> 22057.19 | K13: =H13*Premissas!$B$28 -> 18968.476 | L13: =K13-B13 -> 10968.476 | M13: =K13/B13 -> 2.3710595 | N13: =Premissas!$B$6+H13*Premissas!$B$12 -> 301 | O13: =IF(G13>Premissas!$B$29,"Passa da folga de entradas (35/mês)",IF(N13>Premissas!$B$11,"Lota o teto: fechar vagas","OK")) -> Passa da folga de entradas (35/mês) | P13: =IF(H13*Premissas!$B$12<Premissas!$B$11-Premissas!$B$6,"Não lota",(Premissas!$B$11-Premissas!$B$6)/H13) -> 2.2631579 | Q13: =Premissas!$B$30*E13 -> 1075
A15: Como ler: Contribuição = alunos novos × (LTV − custo de atendimento no período). Resultado líquido = contribuição − verba do mês.
A16: O resultado considera a permanência (6 meses) dos alunos captados no mês, não o caixa do mês; a coluna de receita da 1ª compra mostra o caixa de entrada.
A17: Quando o potencial passa da folga de entradas, os alunos excedentes não entram na conta e a verba excedente vira desperdício (ver alerta).
A18: Base ativa em regime = alunos ativos hoje + alunos novos por mês × permanência, se as vagas nunca fechassem. Com o teto de alunos ativos, os valores mensais acima só valem enquanto há vaga.
A19: A aba Evolução mostra mês a mês o que acontece com o teto: a base lota, as vagas fecham e a verba cai para o nível de manutenção.

Sheet Evolução
A1: Evolução mensal da base com teto de alunos ativos e lista de espera (12 meses)
A2: Simulação simplificada: cada aluno captado fica exatamente o número de meses de permanência. Com a base no teto, as vagas fecham; a campanha normal pausa e só roda a campanha enxuta de lista de espera.
A3: Cenário (1 = Conservador, 2 = Realista, 3 = Otimista) | B3: 2 | C3: {=INDEX(Premissas!A33:A35,B3)} -> Realista
A4: Verba máxima por mês, campanha normal (R$) | B4: 5000 | C4: Gasta enquanto há vaga; pausa com vagas fechadas
A5: CAC do cenário (R$) | B5: {=INDEX(Premissas!D33:D35,B3)} -> 291.66667
A6: Alunos ativos hoje · teto | B6: =Premissas!B6 -> 187 | C6: =Premissas!B11 -> 230
A7: Contribuição por aluno novo (R$) · folga de entradas/mês | B7: =Premissas!B28 -> 998.34085 | C7: =Premissas!B29 -> 19
A8: Verba mensal da campanha de lista de espera (R$) | B8: 1000 | C8: HIPÓTESE minha. Gasta só com vagas fechadas. Coloque 0 para pausar tudo e comparar
A9: CPL da lista de espera, em % do CPL do cenário · resultado em R$ | B9: 1 | C9: {=INDEX(Premissas!B33:B35,B3)*B9} -> 35 | D9: HIPÓTESE minha. 100% = mesmo custo do lead da campanha normal (conservador)
A10: Conversão da espera na reabertura, em % do fechamento do cenário · resultado | B10: 0.5 | C10: {=INDEX(Premissas!C33:C35,B3)*B10} -> 0.06 | D10: HIPÓTESE minha. Lead que espera semanas tende a converter menos; validar na prática
A12: Mês | B12: Vagas livres no teto | C12: Lista de espera no início (leads) | D12: Alunos da espera admitidos | E12: Alunos que a verba normal compra | F12: Alunos pagos admitidos | G12: Total de alunos admitidos | H12: Alunos ativos ao fim do mês | I12: Verba campanha normal (R$) | J12: Verba lista de espera (R$) | K12: Novos leads na espera | L12: Lista de espera no fim (leads) | M12: Contribuição dos admitidos (R$) | N12: Resultado do mês (R$) | O12: Situação | P12: Lotou (1 = sim)
A13: 1 | B13: =MAX(0,$C$6-($B$6+0)) -> 43 | C13: 0 | D13: =IF($C$10>0,MIN(C13*$C$10,B13,$C$7),0) -> 0 | E13: =MAX(0,MIN($B$4/$B$5,$C$7-D13)) -> 17.142857 | F13: =MIN(E13,B13-D13) -> 17.142857 | G13: =D13+F13 -> 17.142857 | H13: =$B$6+SUM(G13) -> 204.14286 | I13: =F13*$B$5 -> 5000 | J13: =IF(B13<=0,$B$8,0) -> 0 | K13: =IF($C$9>0,J13/$C$9,0) -> 0 | L13: =C13-IF($C$10>0,D13/$C$10,0)+K13 -> 0 | M13: =G13*$B$7 -> 17114.414 | N13: =M13-I13-J13 -> 12114.414 | O13: =IF(B13<=0,"Vagas fechadas",IF(F13<E13,"Vagas limitadas pelo teto","Aberto")) -> Aberto | P13: =IF(H13>=$C$6-0.01,1,0) -> 0
A14: 2 | B14: =MAX(0,$C$6-($B$6+SUM(G13))) -> 25.857143 | C14: =L13 -> 0 | D14: =IF($C$10>0,MIN(C14*$C$10,B14,$C$7),0) -> 0 | E14: =MAX(0,MIN($B$4/$B$5,$C$7-D14)) -> 17.142857 | F14: =MIN(E14,B14-D14) -> 17.142857 | G14: =D14+F14 -> 17.142857 | H14: =$B$6+SUM(G13:G14) -> 221.28571 | I14: =F14*$B$5 -> 5000 | J14: =IF(B14<=0,$B$8,0) -> 0 | K14: =IF($C$9>0,J14/$C$9,0) -> 0 | L14: =C14-IF($C$10>0,D14/$C$10,0)+K14 -> 0 | M14: =G14*$B$7 -> 17114.414 | N14: =M14-I14-J14 -> 12114.414 | O14: =IF(B14<=0,"Vagas fechadas",IF(F14<E14,"Vagas limitadas pelo teto","Aberto")) -> Aberto | P14: =IF(H14>=$C$6-0.01,1,0) -> 0
A15: 3 | B15: =MAX(0,$C$6-($B$6+SUM(G13:G14))) -> 8.7142857 | C15: =L14 -> 0 | D15: =IF($C$10>0,MIN(C15*$C$10,B15,$C$7),0) -> 0 | E15: =MAX(0,MIN($B$4/$B$5,$C$7-D15)) -> 17.142857 | F15: =MIN(E15,B15-D15) -> 8.7142857 | G15: =D15+F15 -> 8.7142857 | H15: =$B$6+SUM(G13:G15) -> 230 | I15: =F15*$B$5 -> 2541.6667 | J15: =IF(B15<=0,$B$8,0) -> 0 | K15: =IF($C$9>0,J15/$C$9,0) -> 0 | L15: =C15-IF($C$10>0,D15/$C$10,0)+K15 -> 0 | M15: =G15*$B$7 -> 8699.8274 | N15: =M15-I15-J15 -> 6158.1607 | O15: =IF(B15<=0,"Vagas fechadas",IF(F15<E15,"Vagas limitadas pelo teto","Aberto")) -> Vagas limitadas pelo teto | P15: =IF(H15>=$C$6-0.01,1,0) -> 1
A16: 4 | B16: =MAX(0,$C$6-($B$6+SUM(G13:G15))) -> 0 | C16: =L15 -> 0 | D16: =IF($C$10>0,MIN(C16*$C$10,B16,$C$7),0) -> 0 | E16: =MAX(0,MIN($B$4/$B$5,$C$7-D16)) -> 17.142857 | F16: =MIN(E16,B16-D16) -> 0 | G16: =D16+F16 -> 0 | H16: =$B$6+SUM(G13:G16) -> 230 | I16: =F16*$B$5 -> 0 | J16: =IF(B16<=0,$B$8,0) -> 1000 | K16: =IF($C$9>0,J16/$C$9,0) -> 28.571429 | L16: =C16-IF($C$10>0,D16/$C$10,0)+K16 -> 28.571429 | M16: =G16*$B$7 -> 0 | N16: =M16-I16-J16 -> -1000 | O16: =IF(B16<=0,"Vagas fechadas",IF(F16<E16,"Vagas limitadas pelo teto","Aberto")) -> Vagas fechadas | P16: =IF(H16>=$C$6-0.01,1,0) -> 1
A17: 5 | B17: =MAX(0,$C$6-($B$6+SUM(G13:G16))) -> 0 | C17: =L16 -> 28.571429 | D17: =IF($C$10>0,MIN(C17*$C$10,B17,$C$7),0) -> 0 | E17: =MAX(0,MIN($B$4/$B$5,$C$7-D17)) -> 17.142857 | F17: =MIN(E17,B17-D17) -> 0 | G17: =D17+F17 -> 0 | H17: =$B$6+SUM(G13:G17) -> 230 | I17: =F17*$B$5 -> 0 | J17: =IF(B17<=0,$B$8,0) -> 1000 | K17: =IF($C$9>0,J17/$C$9,0) -> 28.571429 | L17: =C17-IF($C$10>0,D17/$C$10,0)+K17 -> 57.142857 | M17: =G17*$B$7 -> 0 | N17: =M17-I17-J17 -> -1000 | O17: =IF(B17<=0,"Vagas fechadas",IF(F17<E17,"Vagas limitadas pelo teto","Aberto")) -> Vagas fechadas | P17: =IF(H17>=$C$6-0.01,1,0) -> 1
A18: 6 | B18: =MAX(0,$C$6-($B$6+SUM(G13:G17))) -> 0 | C18: =L17 -> 57.142857 | D18: =IF($C$10>0,MIN(C18*$C$10,B18,$C$7),0) -> 0 | E18: =MAX(0,MIN($B$4/$B$5,$C$7-D18)) -> 17.142857 | F18: =MIN(E18,B18-D18) -> 0 | G18: =D18+F18 -> 0 | H18: =$B$6+SUM(G13:G18) -> 230 | I18: =F18*$B$5 -> 0 | J18: =IF(B18<=0,$B$8,0) -> 1000 | K18: =IF($C$9>0,J18/$C$9,0) -> 28.571429 | L18: =C18-IF($C$10>0,D18/$C$10,0)+K18 -> 85.714286 | M18: =G18*$B$7 -> 0 | N18: =M18-I18-J18 -> -1000 | O18: =IF(B18<=0,"Vagas fechadas",IF(F18<E18,"Vagas limitadas pelo teto","Aberto")) -> Vagas fechadas | P18: =IF(H18>=$C$6-0.01,1,0) -> 1
A19: 7 | B19: =MAX(0,$C$6-($B$6+SUM(G14:G18))) -> 17.142857 | C19: =L18 -> 85.714286 | D19: =IF($C$10>0,MIN(C19*$C$10,B19,$C$7),0) -> 5.1428571 | E19: =MAX(0,MIN($B$4/$B$5,$C$7-D19)) -> 13.857143 | F19: =MIN(E19,B19-D19) -> 12 | G19: =D19+F19 -> 17.142857 | H19: =$B$6+SUM(G14:G19) -> 230 | I19: =F19*$B$5 -> 3500 | J19: =IF(B19<=0,$B$8,0) -> 0 | K19: =IF($C$9>0,J19/$C$9,0) -> 0 | L19: =C19-IF($C$10>0,D19/$C$10,0)+K19 -> 0 | M19: =G19*$B$7 -> 17114.414 | N19: =M19-I19-J19 -> 13614.414 | O19: =IF(B19<=0,"Vagas fechadas",IF(F19<E19,"Vagas limitadas pelo teto","Aberto")) -> Vagas limitadas pelo teto | P19: =IF(H19>=$C$6-0.01,1,0) -> 1
A20: 8 | B20: =MAX(0,$C$6-($B$6+SUM(G15:G19))) -> 17.142857 | C20: =L19 -> 0 | D20: =IF($C$10>0,MIN(C20*$C$10,B20,$C$7),0) -> 0 | E20: =MAX(0,MIN($B$4/$B$5,$C$7-D20)) -> 17.142857 | F20: =MIN(E20,B20-D20) -> 17.142857 | G20: =D20+F20 -> 17.142857 | H20: =$B$6+SUM(G15:G20) -> 230 | I20: =F20*$B$5 -> 5000 | J20: =IF(B20<=0,$B$8,0) -> 0 | K20: =IF($C$9>0,J20/$C$9,0) -> 0 | L20: =C20-IF($C$10>0,D20/$C$10,0)+K20 -> 0 | M20: =G20*$B$7 -> 17114.414 | N20: =M20-I20-J20 -> 12114.414 | O20: =IF(B20<=0,"Vagas fechadas",IF(F20<E20,"Vagas limitadas pelo teto","Aberto")) -> Aberto | P20: =IF(H20>=$C$6-0.01,1,0) -> 1
A21: 9 | B21: =MAX(0,$C$6-($B$6+SUM(G16:G20))) -> 8.7142857 | C21: =L20 -> 0 | D21: =IF($C$10>0,MIN(C21*$C$10,B21,$C$7),0) -> 0 | E21: =MAX(0,MIN($B$4/$B$5,$C$7-D21)) -> 17.142857 | F21: =MIN(E21,B21-D21) -> 8.7142857 | G21: =D21+F21 -> 8.7142857 | H21: =$B$6+SUM(G16:G21) -> 230 | I21: =F21*$B$5 -> 2541.6667 | J21: =IF(B21<=0,$B$8,0) -> 0 | K21: =IF($C$9>0,J21/$C$9,0) -> 0 | L21: =C21-IF($C$10>0,D21/$C$10,0)+K21 -> 0 | M21: =G21*$B$7 -> 8699.8274 | N21: =M21-I21-J21 -> 6158.1607 | O21: =IF(B21<=0,"Vagas fechadas",IF(F21<E21,"Vagas limitadas pelo teto","Aberto")) -> Vagas limitadas pelo teto | P21: =IF(H21>=$C$6-0.01,1,0) -> 1
A22: 10 | B22: =MAX(0,$C$6-($B$6+SUM(G17:G21))) -> 0 | C22: =L21 -> 0 | D22: =IF($C$10>0,MIN(C22*$C$10,B22,$C$7),0) -> 0 | E22: =MAX(0,MIN($B$4/$B$5,$C$7-D22)) -> 17.142857 | F22: =MIN(E22,B22-D22) -> 0 | G22: =D22+F22 -> 0 | H22: =$B$6+SUM(G17:G22) -> 230 | I22: =F22*$B$5 -> 0 | J22: =IF(B22<=0,$B$8,0) -> 1000 | K22: =IF($C$9>0,J22/$C$9,0) -> 28.571429 | L22: =C22-IF($C$10>0,D22/$C$10,0)+K22 -> 28.571429 | M22: =G22*$B$7 -> 0 | N22: =M22-I22-J22 -> -1000 | O22: =IF(B22<=0,"Vagas fechadas",IF(F22<E22,"Vagas limitadas pelo teto","Aberto")) -> Vagas fechadas | P22: =IF(H22>=$C$6-0.01,1,0) -> 1
A23: 11 | B23: =MAX(0,$C$6-($B$6+SUM(G18:G22))) -> 0 | C23: =L22 -> 28.571429 | D23: =IF($C$10>0,MIN(C23*$C$10,B23,$C$7),0) -> 0 | E23: =MAX(0,MIN($B$4/$B$5,$C$7-D23)) -> 17.142857 | F23: =MIN(E23,B23-D23) -> 0 | G23: =D23+F23 -> 0 | H23: =$B$6+SUM(G18:G23) -> 230 | I23: =F23*$B$5 -> 0 | J23: =IF(B23<=0,$B$8,0) -> 1000 | K23: =IF($C$9>0,J23/$C$9,0) -> 28.571429 | L23: =C23-IF($C$10>0,D23/$C$10,0)+K23 -> 57.142857 | M23: =G23*$B$7 -> 0 | N23: =M23-I23-J23 -> -1000 | O23: =IF(B23<=0,"Vagas fechadas",IF(F23<E23,"Vagas limitadas pelo teto","Aberto")) -> Vagas fechadas | P23: =IF(H23>=$C$6-0.01,1,0) -> 1
A24: 12 | B24: =MAX(0,$C$6-($B$6+SUM(G19:G23))) -> 0 | C24: =L23 -> 57.142857 | D24: =IF($C$10>0,MIN(C24*$C$10,B24,$C$7),0) -> 0 | E24: =MAX(0,MIN($B$4/$B$5,$C$7-D24)) -> 17.142857 | F24: =MIN(E24,B24-D24) -> 0 | G24: =D24+F24 -> 0 | H24: =$B$6+SUM(G19:G24) -> 230 | I24: =F24*$B$5 -> 0 | J24: =IF(B24<=0,$B$8,0) -> 1000 | K24: =IF($C$9>0,J24/$C$9,0) -> 28.571429 | L24: =C24-IF($C$10>0,D24/$C$10,0)+K24 -> 85.714286 | M24: =G24*$B$7 -> 0 | N24: =M24-I24-J24 -> -1000 | O24: =IF(B24<=0,"Vagas fechadas",IF(F24<E24,"Vagas limitadas pelo teto","Aberto")) -> Vagas fechadas | P24: =IF(H24>=$C$6-0.01,1,0) -> 1
A25: Total 12 meses | D25: =SUM(D13:D24) -> 5.1428571 | F25: =SUM(F13:F24) -> 80.857143 | G25: =SUM(G13:G24) -> 86 | I25: =SUM(I13:I24) -> 23583.333 | J25: =SUM(J13:J24) -> 6000 | K25: =SUM(K13:K24) -> 171.42857 | M25: =SUM(M13:M24) -> 85857.313 | N25: =SUM(N13:N24) -> 56273.979
A27: RESUMO
A28: Primeiro mês em que a base lota o teto | B28: =IFERROR(MATCH(1,P13:P24,0),"Não lota") -> 3
A29: Verba mensal de manutenção da campanha normal, com a base no teto (R$) | B29: =Premissas!B30*B5 -> 2090.2778 | C29: Entradas extras sustentáveis × CAC do cenário
A30: Verba total em 12 meses (normal + espera) (R$) | B30: =I25+J25 -> 29583.333
A31: Alunos admitidos em 12 meses · dos quais vindos da lista de espera | B31: =G25 -> 86 | C31: =D25 -> 5.1428571
A32: CAC médio dos 12 meses (R$) | B32: =IF(G25>0,(I25+J25)/G25,0) -> 343.99225
A33: Retorno dos 12 meses (contribuição ÷ verba total) | B33: =IF(I25+J25>0,M25/(I25+J25),0) -> 2.902219
A34: CAC de um aluno vindo da lista de espera (R$) | B34: =IF(C10>0,C9/C10,0) -> 583.33333 | C34: CPL da espera ÷ conversão da espera
A35: CAC de um aluno vindo da campanha normal (R$) | B35: =B5 -> 291.66667
A36: Leitura | B36: =IF(B35=0,"Sem lista de espera",IF(B34<B35,"Com estas hipóteses, a lista de espera sai mais barata por aluno do que o anúncio na reabertura","Com estas hipóteses, o anúncio na reabertura sai mais barato por aluno do que a lista de espera")) -> Com estas hipóteses, o anúncio na reabertura sai mais barato por aluno do que a lista de espera
A38: Como o teto de alunos limita as entradas, quem vem da lista de espera ocupa a vaga de quem viria do anúncio. Por isso a comparação de CAC no resumo é o que decide se vale manter a campanha de espera.
A39: A lista de espera pode ter outro benefício que a simulação não mede: encher as vagas mais rápido na reabertura, sem esperar a campanha normal ganhar tração.
A40: Os leads atendidos na reabertura saem da lista, convertam ou não; só sobram leads quando faltam vagas. O envelhecimento do lead só entra pelo desconto de conversão (quanto mais tempo parado, menor a conversão).
A41: Limitação: com permanência fixa de 6 meses, as saídas acontecem em bloco e as vagas abrem e fecham em ondas. Na prática as saídas se espalham.
A42: O resultado de cada mês atribui ao mês da entrada toda a contribuição do aluno (receita menos custo de atendimento nos 6 meses).
A43: Premissas, CPL, fechamento e CAC vêm da aba Premissas; aqui você edita o cenário, a verba e as hipóteses da lista de espera (células amarelas).

Sheet Leads e Alunos
A1: Leads e alunos por faixa de verba, CPL e fechamento
A2: Cada bloco é uma faixa de verba mensal (definida na aba Premissas). À esquerda: leads e alunos novos; à direita: CAC resultante. Os eixos de CPL e fechamento vêm da aba Sensibilidade.
A3: CAC de equilíbrio (R$) | B3: =Premissas!B28 -> 998.34085
A4: Limite 'bom' de CAC (R$) | B4: =Sensibilidade!B5 -> 499.17042
A5: Folga de capacidade (alunos/mês) | B5: =Premissas!B29 -> 19
A6: Cores: alunos em laranja = acima da folga de capacidade · CAC verde até o limite bom, amarelo até o equilíbrio, vermelho acima.
A8: Faixa 1: verba mensal (R$) | B8: =Premissas!$B$38 -> 3000
C9: Alunos novos por mês (potencial), conforme o fechamento | J9: CAC resultante (R$), conforme o fechamento
A10: CPL (R$) | B10: Leads pagos/mês | C10: =Sensibilidade!B$8 -> 0.06 | D10: =Sensibilidade!C$8 -> 0.08 | E10: =Sensibilidade!D$8 -> 0.1 | F10: =Sensibilidade!E$8 -> 0.12 | G10: =Sensibilidade!F$8 -> 0.15 | H10: =Sensibilidade!G$8 -> 0.16666667 | J10: =Sensibilidade!B$8 -> 0.06 | K10: =Sensibilidade!C$8 -> 0.08 | L10: =Sensibilidade!D$8 -> 0.1 | M10: =Sensibilidade!E$8 -> 0.12 | N10: =Sensibilidade!F$8 -> 0.15 | O10: =Sensibilidade!G$8 -> 0.16666667
A11: =Sensibilidade!$A9 -> 20 | B11: =$B$8/A11 -> 150 | C11: =$B11*C$10 -> 9 | D11: =$B11*D$10 -> 12 | E11: =$B11*E$10 -> 15 | F11: =$B11*F$10 -> 18 | G11: =$B11*G$10 -> 22.5 | H11: =$B11*H$10 -> 25 | J11: =$A11/J$10 -> 333.33333 | K11: =$A11/K$10 -> 250 | L11: =$A11/L$10 -> 200 | M11: =$A11/M$10 -> 166.66667 | N11: =$A11/N$10 -> 133.33333 | O11: =$A11/O$10 -> 120
A12: =Sensibilidade!$A10 -> 25 | B12: =$B$8/A12 -> 120 | C12: =$B12*C$10 -> 7.2 | D12: =$B12*D$10 -> 9.6 | E12: =$B12*E$10 -> 12 | F12: =$B12*F$10 -> 14.4 | G12: =$B12*G$10 -> 18 | H12: =$B12*H$10 -> 20 | J12: =$A12/J$10 -> 416.66667 | K12: =$A12/K$10 -> 312.5 | L12: =$A12/L$10 -> 250 | M12: =$A12/M$10 -> 208.33333 | N12: =$A12/N$10 -> 166.66667 | O12: =$A12/O$10 -> 150
A13: =Sensibilidade!$A11 -> 30 | B13: =$B$8/A13 -> 100 | C13: =$B13*C$10 -> 6 | D13: =$B13*D$10 -> 8 | E13: =$B13*E$10 -> 10 | F13: =$B13*F$10 -> 12 | G13: =$B13*G$10 -> 15 | H13: =$B13*H$10 -> 16.666667 | J13: =$A13/J$10 -> 500 | K13: =$A13/K$10 -> 375 | L13: =$A13/L$10 -> 300 | M13: =$A13/M$10 -> 250 | N13: =$A13/N$10 -> 200 | O13: =$A13/O$10 -> 180
A14: =Sensibilidade!$A12 -> 35 | B14: =$B$8/A14 -> 85.714286 | C14: =$B14*C$10 -> 5.1428571 | D14: =$B14*D$10 -> 6.8571429 | E14: =$B14*E$10 -> 8.5714286 | F14: =$B14*F$10 -> 10.285714 | G14: =$B14*G$10 -> 12.857143 | H14: =$B14*H$10 -> 14.285714 | J14: =$A14/J$10 -> 583.33333 | K14: =$A14/K$10 -> 437.5 | L14: =$A14/L$10 -> 350 | M14: =$A14/M$10 -> 291.66667 | N14: =$A14/N$10 -> 233.33333 | O14: =$A14/O$10 -> 210
A15: =Sensibilidade!$A13 -> 40 | B15: =$B$8/A15 -> 75 | C15: =$B15*C$10 -> 4.5 | D15: =$B15*D$10 -> 6 | E15: =$B15*E$10 -> 7.5 | F15: =$B15*F$10 -> 9 | G15: =$B15*G$10 -> 11.25 | H15: =$B15*H$10 -> 12.5 | J15: =$A15/J$10 -> 666.66667 | K15: =$A15/K$10 -> 500 | L15: =$A15/L$10 -> 400 | M15: =$A15/M$10 -> 333.33333 | N15: =$A15/N$10 -> 266.66667 | O15: =$A15/O$10 -> 240
A16: =Sensibilidade!$A14 -> 50 | B16: =$B$8/A16 -> 60 | C16: =$B16*C$10 -> 3.6 | D16: =$B16*D$10 -> 4.8 | E16: =$B16*E$10 -> 6 | F16: =$B16*F$10 -> 7.2 | G16: =$B16*G$10 -> 9 | H16: =$B16*H$10 -> 10 | J16: =$A16/J$10 -> 833.33333 | K16: =$A16/K$10 -> 625 | L16: =$A16/L$10 -> 500 | M16: =$A16/M$10 -> 416.66667 | N16: =$A16/N$10 -> 333.33333 | O16: =$A16/O$10 -> 300
A17: =Sensibilidade!$A15 -> 60 | B17: =$B$8/A17 -> 50 | C17: =$B17*C$10 -> 3 | D17: =$B17*D$10 -> 4 | E17: =$B17*E$10 -> 5 | F17: =$B17*F$10 -> 6 | G17: =$B17*G$10 -> 7.5 | H17: =$B17*H$10 -> 8.3333333 | J17: =$A17/J$10 -> 1000 | K17: =$A17/K$10 -> 750 | L17: =$A17/L$10 -> 600 | M17: =$A17/M$10 -> 500 | N17: =$A17/N$10 -> 400 | O17: =$A17/O$10 -> 360
A18: =Sensibilidade!$A16 -> 80 | B18: =$B$8/A18 -> 37.5 | C18: =$B18*C$10 -> 2.25 | D18: =$B18*D$10 -> 3 | E18: =$B18*E$10 -> 3.75 | F18: =$B18*F$10 -> 4.5 | G18: =$B18*G$10 -> 5.625 | H18: =$B18*H$10 -> 6.25 | J18: =$A18/J$10 -> 1333.3333 | K18: =$A18/K$10 -> 1000 | L18: =$A18/L$10 -> 800 | M18: =$A18/M$10 -> 666.66667 | N18: =$A18/N$10 -> 533.33333 | O18: =$A18/O$10 -> 480
A20: Faixa 2: verba mensal (R$) | B20: =Premissas!$B$39 -> 5000
C21: Alunos novos por mês (potencial), conforme o fechamento | J21: CAC resultante (R$), conforme o fechamento
A22: CPL (R$) | B22: Leads pagos/mês | C22: =Sensibilidade!B$8 -> 0.06 | D22: =Sensibilidade!C$8 -> 0.08 | E22: =Sensibilidade!D$8 -> 0.1 | F22: =Sensibilidade!E$8 -> 0.12 | G22: =Sensibilidade!F$8 -> 0.15 | H22: =Sensibilidade!G$8 -> 0.16666667 | J22: =Sensibilidade!B$8 -> 0.06 | K22: =Sensibilidade!C$8 -> 0.08 | L22: =Sensibilidade!D$8 -> 0.1 | M22: =Sensibilidade!E$8 -> 0.12 | N22: =Sensibilidade!F$8 -> 0.15 | O22: =Sensibilidade!G$8 -> 0.16666667
A23: =Sensibilidade!$A9 -> 20 | B23: =$B$20/A23 -> 250 | C23: =$B23*C$22 -> 15 | D23: =$B23*D$22 -> 20 | E23: =$B23*E$22 -> 25 | F23: =$B23*F$22 -> 30 | G23: =$B23*G$22 -> 37.5 | H23: =$B23*H$22 -> 41.666667 | J23: =$A23/J$22 -> 333.33333 | K23: =$A23/K$22 -> 250 | L23: =$A23/L$22 -> 200 | M23: =$A23/M$22 -> 166.66667 | N23: =$A23/N$22 -> 133.33333 | O23: =$A23/O$22 -> 120
A24: =Sensibilidade!$A10 -> 25 | B24: =$B$20/A24 -> 200 | C24: =$B24*C$22 -> 12 | D24: =$B24*D$22 -> 16 | E24: =$B24*E$22 -> 20 | F24: =$B24*F$22 -> 24 | G24: =$B24*G$22 -> 30 | H24: =$B24*H$22 -> 33.333333 | J24: =$A24/J$22 -> 416.66667 | K24: =$A24/K$22 -> 312.5 | L24: =$A24/L$22 -> 250 | M24: =$A24/M$22 -> 208.33333 | N24: =$A24/N$22 -> 166.66667 | O24: =$A24/O$22 -> 150
A25: =Sensibilidade!$A11 -> 30 | B25: =$B$20/A25 -> 166.66667 | C25: =$B25*C$22 -> 10 | D25: =$B25*D$22 -> 13.333333 | E25: =$B25*E$22 -> 16.666667 | F25: =$B25*F$22 -> 20 | G25: =$B25*G$22 -> 25 | H25: =$B25*H$22 -> 27.777778 | J25: =$A25/J$22 -> 500 | K25: =$A25/K$22 -> 375 | L25: =$A25/L$22 -> 300 | M25: =$A25/M$22 -> 250 | N25: =$A25/N$22 -> 200 | O25: =$A25/O$22 -> 180
A26: =Sensibilidade!$A12 -> 35 | B26: =$B$20/A26 -> 142.85714 | C26: =$B26*C$22 -> 8.5714286 | D26: =$B26*D$22 -> 11.428571 | E26: =$B26*E$22 -> 14.285714 | F26: =$B26*F$22 -> 17.142857 | G26: =$B26*G$22 -> 21.428571 | H26: =$B26*H$22 -> 23.809524 | J26: =$A26/J$22 -> 583.33333 | K26: =$A26/K$22 -> 437.5 | L26: =$A26/L$22 -> 350 | M26: =$A26/M$22 -> 291.66667 | N26: =$A26/N$22 -> 233.33333 | O26: =$A26/O$22 -> 210
A27: =Sensibilidade!$A13 -> 40 | B27: =$B$20/A27 -> 125 | C27: =$B27*C$22 -> 7.5 | D27: =$B27*D$22 -> 10 | E27: =$B27*E$22 -> 12.5 | F27: =$B27*F$22 -> 15 | G27: =$B27*G$22 -> 18.75 | H27: =$B27*H$22 -> 20.833333 | J27: =$A27/J$22 -> 666.66667 | K27: =$A27/K$22 -> 500 | L27: =$A27/L$22 -> 400 | M27: =$A27/M$22 -> 333.33333 | N27: =$A27/N$22 -> 266.66667 | O27: =$A27/O$22 -> 240
A28: =Sensibilidade!$A14 -> 50 | B28: =$B$20/A28 -> 100 | C28: =$B28*C$22 -> 6 | D28: =$B28*D$22 -> 8 | E28: =$B28*E$22 -> 10 | F28: =$B28*F$22 -> 12 | G28: =$B28*G$22 -> 15 | H28: =$B28*H$22 -> 16.666667 | J28: =$A28/J$22 -> 833.33333 | K28: =$A28/K$22 -> 625 | L28: =$A28/L$22 -> 500 | M28: =$A28/M$22 -> 416.66667 | N28: =$A28/N$22 -> 333.33333 | O28: =$A28/O$22 -> 300
A29: =Sensibilidade!$A15 -> 60 | B29: =$B$20/A29 -> 83.333333 | C29: =$B29*C$22 -> 5 | D29: =$B29*D$22 -> 6.6666667 | E29: =$B29*E$22 -> 8.3333333 | F29: =$B29*F$22 -> 10 | G29: =$B29*G$22 -> 12.5 | H29: =$B29*H$22 -> 13.888889 | J29: =$A29/J$22 -> 1000 | K29: =$A29/K$22 -> 750 | L29: =$A29/L$22 -> 600 | M29: =$A29/M$22 -> 500 | N29: =$A29/N$22 -> 400 | O29: =$A29/O$22 -> 360
A30: =Sensibilidade!$A16 -> 80 | B30: =$B$20/A30 -> 62.5 | C30: =$B30*C$22 -> 3.75 | D30: =$B30*D$22 -> 5 | E30: =$B30*E$22 -> 6.25 | F30: =$B30*F$22 -> 7.5 | G30: =$B30*G$22 -> 9.375 | H30: =$B30*H$22 -> 10.416667 | J30: =$A30/J$22 -> 1333.3333 | K30: =$A30/K$22 -> 1000 | L30: =$A30/L$22 -> 800 | M30: =$A30/M$22 -> 666.66667 | N30: =$A30/N$22 -> 533.33333 | O30: =$A30/O$22 -> 480
A32: Faixa 3: verba mensal (R$) | B32: =Premissas!$B$40 -> 8000
C33: Alunos novos por mês (potencial), conforme o fechamento | J33: CAC resultante (R$), conforme o fechamento
A34: CPL (R$) | B34: Leads pagos/mês | C34: =Sensibilidade!B$8 -> 0.06 | D34: =Sensibilidade!C$8 -> 0.08 | E34: =Sensibilidade!D$8 -> 0.1 | F34: =Sensibilidade!E$8 -> 0.12 | G34: =Sensibilidade!F$8 -> 0.15 | H34: =Sensibilidade!G$8 -> 0.16666667 | J34: =Sensibilidade!B$8 -> 0.06 | K34: =Sensibilidade!C$8 -> 0.08 | L34: =Sensibilidade!D$8 -> 0.1 | M34: =Sensibilidade!E$8 -> 0.12 | N34: =Sensibilidade!F$8 -> 0.15 | O34: =Sensibilidade!G$8 -> 0.16666667
A35: =Sensibilidade!$A9 -> 20 | B35: =$B$32/A35 -> 400 | C35: =$B35*C$34 -> 24 | D35: =$B35*D$34 -> 32 | E35: =$B35*E$34 -> 40 | F35: =$B35*F$34 -> 48 | G35: =$B35*G$34 -> 60 | H35: =$B35*H$34 -> 66.666667 | J35: =$A35/J$34 -> 333.33333 | K35: =$A35/K$34 -> 250 | L35: =$A35/L$34 -> 200 | M35: =$A35/M$34 -> 166.66667 | N35: =$A35/N$34 -> 133.33333 | O35: =$A35/O$34 -> 120
A36: =Sensibilidade!$A10 -> 25 | B36: =$B$32/A36 -> 320 | C36: =$B36*C$34 -> 19.2 | D36: =$B36*D$34 -> 25.6 | E36: =$B36*E$34 -> 32 | F36: =$B36*F$34 -> 38.4 | G36: =$B36*G$34 -> 48 | H36: =$B36*H$34 -> 53.333333 | J36: =$A36/J$34 -> 416.66667 | K36: =$A36/K$34 -> 312.5 | L36: =$A36/L$34 -> 250 | M36: =$A36/M$34 -> 208.33333 | N36: =$A36/N$34 -> 166.66667 | O36: =$A36/O$34 -> 150
A37: =Sensibilidade!$A11 -> 30 | B37: =$B$32/A37 -> 266.66667 | C37: =$B37*C$34 -> 16 | D37: =$B37*D$34 -> 21.333333 | E37: =$B37*E$34 -> 26.666667 | F37: =$B37*F$34 -> 32 | G37: =$B37*G$34 -> 40 | H37: =$B37*H$34 -> 44.444444 | J37: =$A37/J$34 -> 500 | K37: =$A37/K$34 -> 375 | L37: =$A37/L$34 -> 300 | M37: =$A37/M$34 -> 250 | N37: =$A37/N$34 -> 200 | O37: =$A37/O$34 -> 180
A38: =Sensibilidade!$A12 -> 35 | B38: =$B$32/A38 -> 228.57143 | C38: =$B38*C$34 -> 13.714286 | D38: =$B38*D$34 -> 18.285714 | E38: =$B38*E$34 -> 22.857143 | F38: =$B38*F$34 -> 27.428571 | G38: =$B38*G$34 -> 34.285714 | H38: =$B38*H$34 -> 38.095238 | J38: =$A38/J$34 -> 583.33333 | K38: =$A38/K$34 -> 437.5 | L38: =$A38/L$34 -> 350 | M38: =$A38/M$34 -> 291.66667 | N38: =$A38/N$34 -> 233.33333 | O38: =$A38/O$34 -> 210
A39: =Sensibilidade!$A13 -> 40 | B39: =$B$32/A39 -> 200 | C39: =$B39*C$34 -> 12 | D39: =$B39*D$34 -> 16 | E39: =$B39*E$34 -> 20 | F39: =$B39*F$34 -> 24 | G39: =$B39*G$34 -> 30 | H39: =$B39*H$34 -> 33.333333 | J39: =$A39/J$34 -> 666.66667 | K39: =$A39/K$34 -> 500 | L39: =$A39/L$34 -> 400 | M39: =$A39/M$34 -> 333.33333 | N39: =$A39/N$34 -> 266.66667 | O39: =$A39/O$34 -> 240
A40: =Sensibilidade!$A14 -> 50 | B40: =$B$32/A40 -> 160 | C40: =$B40*C$34 -> 9.6 | D40: =$B40*D$34 -> 12.8 | E40: =$B40*E$34 -> 16 | F40: =$B40*F$34 -> 19.2 | G40: =$B40*G$34 -> 24 | H40: =$B40*H$34 -> 26.666667 | J40: =$A40/J$34 -> 833.33333 | K40: =$A40/K$34 -> 625 | L40: =$A40/L$34 -> 500 | M40: =$A40/M$34 -> 416.66667 | N40: =$A40/N$34 -> 333.33333 | O40: =$A40/O$34 -> 300
A41: =Sensibilidade!$A15 -> 60 | B41: =$B$32/A41 -> 133.33333 | C41: =$B41*C$34 -> 8 | D41: =$B41*D$34 -> 10.666667 | E41: =$B41*E$34 -> 13.333333 | F41: =$B41*F$34 -> 16 | G41: =$B41*G$34 -> 20 | H41: =$B41*H$34 -> 22.222222 | J41: =$A41/J$34 -> 1000 | K41: =$A41/K$34 -> 750 | L41: =$A41/L$34 -> 600 | M41: =$A41/M$34 -> 500 | N41: =$A41/N$34 -> 400 | O41: =$A41/O$34 -> 360
A42: =Sensibilidade!$A16 -> 80 | B42: =$B$32/A42 -> 100 | C42: =$B42*C$34 -> 6 | D42: =$B42*D$34 -> 8 | E42: =$B42*E$34 -> 10 | F42: =$B42*F$34 -> 12 | G42: =$B42*G$34 -> 15 | H42: =$B42*H$34 -> 16.666667 | J42: =$A42/J$34 -> 1333.3333 | K42: =$A42/K$34 -> 1000 | L42: =$A42/L$34 -> 800 | M42: =$A42/M$34 -> 666.66667 | N42: =$A42/N$34 -> 533.33333 | O42: =$A42/O$34 -> 480

Sheet Sensibilidade
A1: Sensibilidade: CAC conforme CPL e fechamento
A3: CAC de equilíbrio (R$) | B3: =Premissas!B28 -> 998.34085
A4: Margem de segurança (% do CAC de equilíbrio) | B4: 0.5 | C4: Hipótese minha: queremos um CAC de no máximo metade do equilíbrio
A5: Limite 'bom' de CAC (R$) | B5: =B3*B4 -> 499.17042
A7: CAC (R$) por CPL × fechamento · verde: até o limite bom · amarelo: até o equilíbrio · vermelho: acima do equilíbrio
A8: CPL (R$) ↓ / Fechamento → | B8: 0.06 | C8: 0.08 | D8: 0.1 | E8: 0.12 | F8: 0.15 | G8: =1/6 -> 0.16666667
A9: 20 | B9: =$A9/B$8 -> 333.33333 | C9: =$A9/C$8 -> 250 | D9: =$A9/D$8 -> 200 | E9: =$A9/E$8 -> 166.66667 | F9: =$A9/F$8 -> 133.33333 | G9: =$A9/G$8 -> 120
A10: 25 | B10: =$A10/B$8 -> 416.66667 | C10: =$A10/C$8 -> 312.5 | D10: =$A10/D$8 -> 250 | E10: =$A10/E$8 -> 208.33333 | F10: =$A10/F$8 -> 166.66667 | G10: =$A10/G$8 -> 150
A11: 30 | B11: =$A11/B$8 -> 500 | C11: =$A11/C$8 -> 375 | D11: =$A11/D$8 -> 300 | E11: =$A11/E$8 -> 250 | F11: =$A11/F$8 -> 200 | G11: =$A11/G$8 -> 180
A12: 35 | B12: =$A12/B$8 -> 583.33333 | C12: =$A12/C$8 -> 437.5 | D12: =$A12/D$8 -> 350 | E12: =$A12/E$8 -> 291.66667 | F12: =$A12/F$8 -> 233.33333 | G12: =$A12/G$8 -> 210
A13: 40 | B13: =$A13/B$8 -> 666.66667 | C13: =$A13/C$8 -> 500 | D13: =$A13/D$8 -> 400 | E13: =$A13/E$8 -> 333.33333 | F13: =$A13/F$8 -> 266.66667 | G13: =$A13/G$8 -> 240
A14: 50 | B14: =$A14/B$8 -> 833.33333 | C14: =$A14/C$8 -> 625 | D14: =$A14/D$8 -> 500 | E14: =$A14/E$8 -> 416.66667 | F14: =$A14/F$8 -> 333.33333 | G14: =$A14/G$8 -> 300
A15: 60 | B15: =$A15/B$8 -> 1000 | C15: =$A15/C$8 -> 750 | D15: =$A15/D$8 -> 600 | E15: =$A15/E$8 -> 500 | F15: =$A15/F$8 -> 400 | G15: =$A15/G$8 -> 360
A16: 80 | B16: =$A16/B$8 -> 1333.3333 | C16: =$A16/C$8 -> 1000 | D16: =$A16/D$8 -> 800 | E16: =$A16/E$8 -> 666.66667 | F16: =$A16/F$8 -> 533.33333 | G16: =$A16/G$8 -> 480
A18: Alunos novos por mês para a verba abaixo (sem o teto de capacidade)
A19: Verba mensal analisada (R$) | B19: =Premissas!B39 -> 5000 | C19: Puxa a Faixa 2 da aba Premissas; todas as faixas estão na aba Leads e Alunos
A20: CPL (R$) ↓ / Fechamento → | B20: =B$8 -> 0.06 | C20: =C$8 -> 0.08 | D20: =D$8 -> 0.1 | E20: =E$8 -> 0.12 | F20: =F$8 -> 0.15 | G20: =G$8 -> 0.16666667
A21: =A9 -> 20 | B21: =$B$19/$A21*B$20 -> 15 | C21: =$B$19/$A21*C$20 -> 20 | D21: =$B$19/$A21*D$20 -> 25 | E21: =$B$19/$A21*E$20 -> 30 | F21: =$B$19/$A21*F$20 -> 37.5 | G21: =$B$19/$A21*G$20 -> 41.666667
A22: =A10 -> 25 | B22: =$B$19/$A22*B$20 -> 12 | C22: =$B$19/$A22*C$20 -> 16 | D22: =$B$19/$A22*D$20 -> 20 | E22: =$B$19/$A22*E$20 -> 24 | F22: =$B$19/$A22*F$20 -> 30 | G22: =$B$19/$A22*G$20 -> 33.333333
A23: =A11 -> 30 | B23: =$B$19/$A23*B$20 -> 10 | C23: =$B$19/$A23*C$20 -> 13.333333 | D23: =$B$19/$A23*D$20 -> 16.666667 | E23: =$B$19/$A23*E$20 -> 20 | F23: =$B$19/$A23*F$20 -> 25 | G23: =$B$19/$A23*G$20 -> 27.777778
A24: =A12 -> 35 | B24: =$B$19/$A24*B$20 -> 8.5714286 | C24: =$B$19/$A24*C$20 -> 11.428571 | D24: =$B$19/$A24*D$20 -> 14.285714 | E24: =$B$19/$A24*E$20 -> 17.142857 | F24: =$B$19/$A24*F$20 -> 21.428571 | G24: =$B$19/$A24*G$20 -> 23.809524
A25: =A13 -> 40 | B25: =$B$19/$A25*B$20 -> 7.5 | C25: =$B$19/$A25*C$20 -> 10 | D25: =$B$19/$A25*D$20 -> 12.5 | E25: =$B$19/$A25*E$20 -> 15 | F25: =$B$19/$A25*F$20 -> 18.75 | G25: =$B$19/$A25*G$20 -> 20.833333
A26: =A14 -> 50 | B26: =$B$19/$A26*B$20 -> 6 | C26: =$B$19/$A26*C$20 -> 8 | D26: =$B$19/$A26*D$20 -> 10 | E26: =$B$19/$A26*E$20 -> 12 | F26: =$B$19/$A26*F$20 -> 15 | G26: =$B$19/$A26*G$20 -> 16.666667
A27: =A15 -> 60 | B27: =$B$19/$A27*B$20 -> 5 | C27: =$B$19/$A27*C$20 -> 6.6666667 | D27: =$B$19/$A27*D$20 -> 8.3333333 | E27: =$B$19/$A27*E$20 -> 10 | F27: =$B$19/$A27*F$20 -> 12.5 | G27: =$B$19/$A27*G$20 -> 13.888889
A28: =A16 -> 80 | B28: =$B$19/$A28*B$20 -> 3.75 | C28: =$B$19/$A28*C$20 -> 5 | D28: =$B$19/$A28*D$20 -> 6.25 | E28: =$B$19/$A28*E$20 -> 7.5 | F28: =$B$19/$A28*F$20 -> 9.375 | G28: =$B$19/$A28*G$20 -> 10.416667
